{
  "cells": [
    {
      "cell_type": "markdown",
      "metadata": {
        "id": "8Tyr-_EEmK6s"
      },
      "source": [
        "#TEXT MINING\n",
        "\n",
        "UNRN\n",
        "\n",
        "Especialización en ciencias de datos aplicada\n",
        "\n",
        "Natalia Debandi\n",
        "\n",
        "ndebandi@unrn.edu.ar\n",
        "\n",
        "**CLASE 2**\n",
        "\n",
        "EMBEDINGS\n",
        "\n"
      ]
    },
    {
      "cell_type": "code",
      "source": [
        "!pip install sklearn"
      ],
      "metadata": {
        "id": "KEqkx7xdFBRs",
        "outputId": "cb82e99a-b065-4b7e-9c62-d351c5285d35",
        "colab": {
          "base_uri": "https://localhost:8080/"
        }
      },
      "execution_count": 4,
      "outputs": [
        {
          "output_type": "stream",
          "name": "stdout",
          "text": [
            "Collecting sklearn\n",
            "  Using cached sklearn-0.0.post12.tar.gz (2.6 kB)\n",
            "  \u001b[1;31merror\u001b[0m: \u001b[1msubprocess-exited-with-error\u001b[0m\n",
            "  \n",
            "  \u001b[31m×\u001b[0m \u001b[32mpython setup.py egg_info\u001b[0m did not run successfully.\n",
            "  \u001b[31m│\u001b[0m exit code: \u001b[1;36m1\u001b[0m\n",
            "  \u001b[31m╰─>\u001b[0m See above for output.\n",
            "  \n",
            "  \u001b[1;35mnote\u001b[0m: This error originates from a subprocess, and is likely not a problem with pip.\n",
            "  Preparing metadata (setup.py) ... \u001b[?25l\u001b[?25herror\n",
            "\u001b[1;31merror\u001b[0m: \u001b[1mmetadata-generation-failed\u001b[0m\n",
            "\n",
            "\u001b[31m×\u001b[0m Encountered error while generating package metadata.\n",
            "\u001b[31m╰─>\u001b[0m See above for output.\n",
            "\n",
            "\u001b[1;35mnote\u001b[0m: This is an issue with the package mentioned above, not pip.\n",
            "\u001b[1;36mhint\u001b[0m: See above for details.\n"
          ]
        }
      ]
    },
    {
      "cell_type": "code",
      "source": [
        "!pip install gensim"
      ],
      "metadata": {
        "colab": {
          "base_uri": "https://localhost:8080/"
        },
        "id": "ZYjmT9G6Eu7Y",
        "outputId": "981e7312-2f4f-4aca-fcad-a30dc8a8aafc"
      },
      "execution_count": 3,
      "outputs": [
        {
          "output_type": "stream",
          "name": "stdout",
          "text": [
            "Collecting sklearn\n",
            "  Using cached sklearn-0.0.post12.tar.gz (2.6 kB)\n",
            "  \u001b[1;31merror\u001b[0m: \u001b[1msubprocess-exited-with-error\u001b[0m\n",
            "  \n",
            "  \u001b[31m×\u001b[0m \u001b[32mpython setup.py egg_info\u001b[0m did not run successfully.\n",
            "  \u001b[31m│\u001b[0m exit code: \u001b[1;36m1\u001b[0m\n",
            "  \u001b[31m╰─>\u001b[0m See above for output.\n",
            "  \n",
            "  \u001b[1;35mnote\u001b[0m: This error originates from a subprocess, and is likely not a problem with pip.\n",
            "  Preparing metadata (setup.py) ... \u001b[?25l\u001b[?25herror\n",
            "\u001b[1;31merror\u001b[0m: \u001b[1mmetadata-generation-failed\u001b[0m\n",
            "\n",
            "\u001b[31m×\u001b[0m Encountered error while generating package metadata.\n",
            "\u001b[31m╰─>\u001b[0m See above for output.\n",
            "\n",
            "\u001b[1;35mnote\u001b[0m: This is an issue with the package mentioned above, not pip.\n",
            "\u001b[1;36mhint\u001b[0m: See above for details.\n"
          ]
        }
      ]
    },
    {
      "cell_type": "code",
      "source": [
        "import warnings\n",
        "warnings.filterwarnings('ignore')\n",
        "\n",
        "from gensim.models import Word2Vec, KeyedVectors\n",
        "from gensim.test.utils import common_texts\n",
        "import numpy as np\n",
        "import matplotlib.pyplot as plt\n",
        "from sklearn.decomposition import PCA\n",
        "from sklearn.metrics.pairwise import cosine_similarity"
      ],
      "metadata": {
        "id": "UV2QvDPGE41S",
        "outputId": "a4a61ac4-4a5d-4e3c-b60d-646689d01045",
        "colab": {
          "base_uri": "https://localhost:8080/",
          "height": 383
        }
      },
      "execution_count": 2,
      "outputs": [
        {
          "output_type": "error",
          "ename": "ModuleNotFoundError",
          "evalue": "No module named 'gensim'",
          "traceback": [
            "\u001b[0;31m---------------------------------------------------------------------------\u001b[0m",
            "\u001b[0;31mModuleNotFoundError\u001b[0m                       Traceback (most recent call last)",
            "\u001b[0;32m<ipython-input-2-2548eeee50f8>\u001b[0m in \u001b[0;36m<cell line: 0>\u001b[0;34m()\u001b[0m\n\u001b[1;32m      2\u001b[0m \u001b[0mwarnings\u001b[0m\u001b[0;34m.\u001b[0m\u001b[0mfilterwarnings\u001b[0m\u001b[0;34m(\u001b[0m\u001b[0;34m'ignore'\u001b[0m\u001b[0;34m)\u001b[0m\u001b[0;34m\u001b[0m\u001b[0;34m\u001b[0m\u001b[0m\n\u001b[1;32m      3\u001b[0m \u001b[0;34m\u001b[0m\u001b[0m\n\u001b[0;32m----> 4\u001b[0;31m \u001b[0;32mfrom\u001b[0m \u001b[0mgensim\u001b[0m\u001b[0;34m.\u001b[0m\u001b[0mmodels\u001b[0m \u001b[0;32mimport\u001b[0m \u001b[0mWord2Vec\u001b[0m\u001b[0;34m,\u001b[0m \u001b[0mKeyedVectors\u001b[0m\u001b[0;34m\u001b[0m\u001b[0;34m\u001b[0m\u001b[0m\n\u001b[0m\u001b[1;32m      5\u001b[0m \u001b[0;32mfrom\u001b[0m \u001b[0mgensim\u001b[0m\u001b[0;34m.\u001b[0m\u001b[0mtest\u001b[0m\u001b[0;34m.\u001b[0m\u001b[0mutils\u001b[0m \u001b[0;32mimport\u001b[0m \u001b[0mcommon_texts\u001b[0m\u001b[0;34m\u001b[0m\u001b[0;34m\u001b[0m\u001b[0m\n\u001b[1;32m      6\u001b[0m \u001b[0;32mimport\u001b[0m \u001b[0mnumpy\u001b[0m \u001b[0;32mas\u001b[0m \u001b[0mnp\u001b[0m\u001b[0;34m\u001b[0m\u001b[0;34m\u001b[0m\u001b[0m\n",
            "\u001b[0;31mModuleNotFoundError\u001b[0m: No module named 'gensim'",
            "",
            "\u001b[0;31m---------------------------------------------------------------------------\u001b[0;32m\nNOTE: If your import is failing due to a missing package, you can\nmanually install dependencies using either !pip or !apt.\n\nTo view examples of installing some common dependencies, click the\n\"Open Examples\" button below.\n\u001b[0;31m---------------------------------------------------------------------------\u001b[0m\n"
          ],
          "errorDetails": {
            "actions": [
              {
                "action": "open_url",
                "actionText": "Open Examples",
                "url": "/notebooks/snippets/importing_libraries.ipynb"
              }
            ]
          }
        }
      ]
    }
  ],
  "metadata": {
    "colab": {
      "provenance": []
    },
    "interpreter": {
      "hash": "3386c84ec0532bab34ae70cc8f30d327d47697366efd1f0b040a1804279813d8"
    },
    "kernelspec": {
      "display_name": "Python 3.8.12 ('venv': venv)",
      "language": "python",
      "name": "python3"
    },
    "language_info": {
      "codemirror_mode": {
        "name": "ipython",
        "version": 3
      },
      "file_extension": ".py",
      "mimetype": "text/x-python",
      "name": "python",
      "nbconvert_exporter": "python",
      "pygments_lexer": "ipython3",
      "version": "3.8.12"
    }
  },
  "nbformat": 4,
  "nbformat_minor": 0
}